Workbook
Name _: #REF!
Name __A65700: '[1]MTO REV.2(ARMOR)'!#REF!
Name __A65800: '[1]MTO REV.2(ARMOR)'!#REF!
Name __A66000: '[1]MTO REV.2(ARMOR)'!#REF!
Name __A67000: '[1]MTO REV.2(ARMOR)'!#REF!
Name __A68000: '[1]MTO REV.2(ARMOR)'!#REF!
Name __A70000: '[1]MTO REV.2(ARMOR)'!#REF!
Name __A75000: '[1]MTO REV.2(ARMOR)'!#REF!
Name __A85000: '[1]MTO REV.2(ARMOR)'!#REF!
Name __CON1: #REF!
Name __CON2: #REF!
Name __NET2: #REF!
Name __NPV11: '[2]Cp>10-Ln<10'!#REF!
Name __npv22: '[2]Ln<20'!#REF!
Name __oto10: [3]VL!#REF!
Name __TH1: [4]T1!$B$11:$AE$118
Name __xlnm.Print_Titles_1: #N/A
Name __xlnm.Print_Titles_2: #N/A
Name _01_11_2001: #N/A
Name _0600003563_1: '[5]DANH MUC'!$A$2+'[5]DANH MUC'!A$3:$B263
Name _1: #N/A
Name _1: #REF!
Name _1_0DATA_DATA2_L: '[6]#REF'!#REF!
Name _1000A01: #N/A
Name _19_01_98: #REF!
Name _1CAP002: [7]MTP!#REF!
Name _2: #N/A
Name _2: #REF!
Name _2_1MACN: #REF!
Name _20_01_98: #REF!
Name _214: #REF!
Name _2STREO7: [8]MTP!#REF!
Name _3_2TNCP: #REF!
Name _30_06_05: #REF!
Name _3N: [9]Tongke!#REF!
Name _4DATA_DATA2_L: '[10]#REF'!#REF!
Name _4GOIC01: [11]MTP!#REF!
Name _4OSLCTT: [11]MTP!#REF!
Name _5Document_array_2_1: NA()
Name _6BNTTTH: [8]MTP1!#REF!
Name _6DCTTBO: [8]MTP1!#REF!
Name _6DD24TT: [8]MTP1!#REF!
Name _6Document_array_3_1: NA()
Name _6FCOTBU: [8]MTP1!#REF!
Name _6LATUBU: [8]MTP1!#REF!
Name _6SDTT24: [8]MTP1!#REF!
Name _6TBUDTT: [8]MTP1!#REF!
Name _6TDDDTT: [8]MTP1!#REF!
Name _6TLTTTH: [8]MTP1!#REF!
Name _6TUBUTT: [8]MTP1!#REF!
Name _6UCLVIS: [8]MTP1!#REF!
Name _7DNCABC: [8]MTP1!#REF!
Name _7HDCTBU: [8]MTP1!#REF!
Name _7PKTUBU: [8]MTP1!#REF!
Name _7TBHT20: [8]MTP1!#REF!
Name _7TBHT30: [8]MTP1!#REF!
Name _7TDCABC: [8]MTP1!#REF!
Name _a16550: '[12]CT -THVLNC'!#REF!
Name _A65700: '[13]MTO REV.2(ARMOR)'!#REF!
Name _A65800: '[13]MTO REV.2(ARMOR)'!#REF!

Sheet foxz

Sheet Bảng 1
A1: Bảng số 01: Phần công việc đã thực hiện
A2: (kèm theo Tờ trình số /TTr-BQLDA ngày tháng năm 2024 của Ban Quản lý dự án đầu tư xây dựng huyện Thanh Miện)
A4: STT | B4: Nội dung công việc hoặc tên gói thầu | C4: Đơn vị thực hiện | D4: Giá trị (đồng) | E4: Văn bản phê duyệt/HĐTV | F4: KHDT!A1
A5: 1 | B5: Gói thầu tư vấn khảo sát, lập Báo cáo kinh tế - kỹ thuật | C5: Công ty Cổ phần khảo sát địa chất và xây dựng Hải Dương | D5: =TH!O15+TH!O17 -> 290446000 | E5: Hợp đồng số 16/2024/HĐ-TVXD ngày 04/01/2024 | F5: Hợp đồng số | G5: QĐ số 12/QĐ-BQLDA ngày 03/01/2024
A6: 2 | B6: Gói thầu tư vấn thẩm tra Báo cáo kinh tế - kỹ thuật | C6: Công ty TNHH một thành viên tư vấn xây dựng 30-10 | D6: =TH!O18 -> 38746000 | E6: QĐ số 13/QĐ-BQLDA ngày 03/01/2024
A7: 3 | B7: Gói thầu thẩm định giá vật tư, thiết bị | C7: Công ty Cổ phần thẩm định giá TMC | D7: =TH!O25 -> 6000000 | E7: QĐ số 33/QĐ-BQLDA ngày 16/01/2024
A8: 4 | B8: Chi phí lập nhiệm vụ khảo sát xây dựng | C8: Ban Quản lý dự án đầu tư xây dựng huyện Thanh Miện | D8: =TH!O16 -> 314000
A9: 5 | B9: Chi phí thẩm định báo cáo kinh tế kỹ thuật | C9: Phòng Kinh tế và Hạ tầng | D9: =TH!O29 -> 725000
A10: Tổng giá trị | D10: =ROUND(SUM(D5:D9),-3) -> 336231000 | F10: =D10-KHDT!C12 -> #REF!
J21: =0.06*0.24 -> 0.0144

Sheet Bảng 2
A1: Bảng số 02: Phần công việc không áp dụng được một trong các hình thức lựa chọn nhà thầu
A2: ='Bảng 1'!A2:E2 -> (kèm theo Tờ trình số /TTr-BQLDA ngày tháng năm 2024 của Ban Quản lý dự án đầu tư xây dựng huyện Thanh Miện)
A4: STT | B4: Nội dung công việc | C4: Đơn vị thực hiện | D4: Giá trị (đồng) | E4: KHDT!A1
A5: 1 | B5: Chi phí Quản lý dự án | C5: Ban Quản lý dự án đầu tư xây dựng huyện Thanh Miện | D5: =TH!O12 -> 202002000
A6: 2 | B6: Chi phí đăng tải thông tin đấu thầu | C6: Ban Quản lý dự án đầu tư xây dựng huyện Thanh Miện | D6: =TH!O28 -> 330000
A7: 3 | B7: Chi phí thẩm tra - phê duyệt quyết toán | C7: Phòng Tài chính - Kế hoạch | D7: =TH!O32 -> 18114000
A8: 4 | B8: =TMDT!B94 -> Chi phí kiểm tra công tác nghiệm thu công trình xây dựng (Thông tư 10/2021/TT-BXD) | C8: Phòng Kinh tế và Hạ tầng | D8: =TH!O30 -> 38513000
A9: 5 | B9: =TMDT!B98 -> Chi phí Dự phòng khối lượng | D9: =TH!O33 -> 259356000
A10: Tổng giá trị thực hiện | D10: =ROUND(SUM(D5:D9),-3) -> 518315000 | E10: =D10-KHDT!C17 -> #REF!
D16: =+TMDT!H83+TMDT!H82-#REF! -> #REF!

Sheet Bảng 3
A1: Phụ lục
A2: KẾ HOẠCH LỰA CHỌN NHÀ THẦU (Lần 1)
A3: DỰ ÁN: CẢI TẠO, NÂNG CẤP ĐƯỜNG XÃ ĐOÀN KẾT, ĐOẠN TỪ ĐƯỜNG TỈNH 392C ĐẾN THÔN TỪ Ô, XÃ TÂN TRÀO
A4: (Kèm theo Quyết định số: /QĐ-BQLDA ngày 03 tháng 01 năm 2025)
A5: STT | B5: Tên chủ đầu tư | C5: Tên gói thầu | E5: Giá gói thầu (đồng) | F5: Nguồn vốn | G5: Hình thức lựa chọn nhà thầu | H5: Phương thức lựa chọn nhà thầu | I5: Thời gian tổ chức lựa chọn nhà thầu | J5: Thời gian bắt đầu tổ chức lựa chọn nhà thầu | K5: Loại hợp đồng | L5: Thời gian thực hiện gói thầu | M5: Tùy chọn mua thêm | N5: Giám sát hoạt động đấu thầu | O5: Nhà thầu trúng thầu
C6: Tên gói thầu | D6: Tóm tắt công việc chính của gói thầu
A7: 1 | B7: Ban Quản lý dự án đầu tư xây dựng huyện Thanh Miện | C7: Gói thầu số 1: Tư vấn khảo sát xây dựng, thí nghiệm | D7: Khảo sát địa hình, khảo sát địa chất, cắm cọc GPMB | E7: 271615000 | F7: Ngân sách huyện | G7: Chỉ định thầu rút gọn | H7: - | I7: 15 ngày | J7: Quý I năm 2025 | K7: Trọn gói | L7: 10 ngày; thời gian thực hiện các nghĩa vụ khác được quy định cụ thể trong hợp đồng | M7: - | N7: Không đề xuất | O7: Công ty Đông Phương
A8: 2 | C8: Gói thầu số 2: Tư vấn lập Báo cáo kinh tế - kỹ thuật | D8: Lập Báo cáo kinh tế - kỹ thuật | E8: 421517000 | G8: Chỉ định thầu rút gọn | H8: - | I8: 15 ngày | J8: Quý I năm 2025 | K8: Trọn gói | L8: 20 ngày; thời gian thực hiện các nghĩa vụ khác được quy định cụ thể trong hợp đồng | M8: - | N8: Không đề xuất | O8: Công ty Cổ phần đầu tư xây dựng Long Thành HD
A9: 3 | C9: Gói thầu số 3: Tư vấn thẩm tra Báo cáo kinh tế - kỹ thuật | D9: Thẩm tra Báo cáo kinh tế - kỹ thuật | E9: 55429000 | G9: Chỉ định thầu rút gọn | H9: - | I9: 15 ngày | J9: Quý I năm 2025 | K9: Trọn gói | L9: 10 ngày; thời gian thực hiện các nghĩa vụ khác được quy định cụ thể trong hợp đồng | M9: - | N9: Không đề xuất | O9: Công ty khảo sát địa chất Hải Dương
A10: 4 | C10: Gói thầu số 4: Tư vấn giám sát khảo sát | D10: Giám sát khảo sát xây dựng | E10: 11060000 | G10: Chỉ định thầu rút gọn | H10: - | I10: 15 ngày | J10: Quý I năm 2025 | K10: Trọn gói | L10: 10 ngày; thời gian thực hiện các nghĩa vụ khác được quy định cụ thể trong hợp đồng | M10: - | N10: Không đề xuất | O10: Công ty Hasu
A11: 5 | C11: Gói thầu số 5: Tư vấn thẩm định giá vật tư, thiết bị | D11: Thẩm định giá vật tư, thiết bị | E11: 10000000 | G11: Chỉ định thầu rút gọn | H11: - | I11: 15 ngày | J11: Quý I năm 2025 | K11: Trọn gói | L11: 10 ngày; thời gian thực hiện các nghĩa vụ khác được quy định cụ thể trong hợp đồng | M11: - | N11: Không đề xuất | O11: Công ty thẩm định giá Hà Nội
A12: Tổng giá gói thầu | E12: =SUM(E7:E11) -> 769621000
D15: 271615000
D16: 8148000
D17: 421517000
D18: =SUM(D15:D17) -> 701280000

Sheet Bảng 4
A1: Bảng số 04: Phần công việc chưa đủ điều kiện lập kế hoạch lựa chọn thầu
A2: ='Bảng 1'!A2:E2 -> (kèm theo Tờ trình số /TTr-BQLDA ngày tháng năm 2024 của Ban Quản lý dự án đầu tư xây dựng huyện Thanh Miện)
A4: STT | B4: Nội dung | C4: Giá trị (đồng)
A5: 1 | B5: Chi phí xây dựng
A6: 2 | B6: Chi phí giám sát thi công xây dựng
A7: 3 | B7: Chi phí lập hồ sơ mời thầu, đánh giá hồ sơ dự thầu gói thầu thi công xây dựng
A8: 4 | B8: Chi phí thẩm định hồ sơ mời thầu, thẩm định kết quả LCNT gói thầu thi công xây dựng
A9: 5 | B9: Chi phí lập hồ sơ mời thầu, đánh giá hồ sơ dự thầu gói thầu tư vấn giám sát thi công
A10: 6 | B10: Chi phí thẩm định HSMT, thẩm định kết quả LCNT gói thầu tư vấn giám sát thi công
A11: 7 | B11: Chi phí tư vấn đăng ký môi trường
A12: 8 | B12: Bảo hiểm công trình đường
A13: 9 | B13: Đảm bảo ATGT thi công
A14: 10 | B14: Chi phí tư vấn kiểm toán độc lập
A15: Tổng giá trị các phần công việc | C15: =ROUND(SUM(C5:C14),-3) -> 0

Sheet Bảng 5
A1: Bảng số 04: Tổng giá trị các phần công việc
A2: ='Bảng 1'!A2:E2 -> (kèm theo Tờ trình số /TTr-BQLDA ngày tháng năm 2024 của Ban Quản lý dự án đầu tư xây dựng huyện Thanh Miện)
A4: STT | B4: Nội dung | C4: Giá trị (đồng)
A5: 1 | B5: Tổng giá trị phần công việc đã thực hiện | C5: ='Bảng 1'!D10 -> 336231000 | D5: 336231000
A6: 2 | B6: Tổng giá trị phần công việc không áp dụng được một trong các hình thức lựa chọn nhà thầu | C6: ='Bảng 2'!D10 -> 518315000 | D6: 518315000
A7: 3 | B7: Tổng giá trị phần công việc thuộc kế hoạch lựa chọn nhà thầu | C7: ='Bảng 3'!E12 -> 769621000 | D7: 6772454000 | F7: =SUM('Bảng 4'!#REF!) -> #REF!
A8: 4 | B8: Tổng giá trị phần công việc chưa đủ điều kiện lập kế hoạch lựa chọn thầu | C8: ='Bảng 4'!C15 -> 0 | D8: 0 | F8: =+'Bảng 3'!#REF!+'Bảng 3'!#REF! -> #REF!
A9: Tổng giá trị các phần công việc | C9: =SUM(C5:C8) -> 1624167000 | D9: 7627000000 | E9: =C10-C9 -> 6002833000 | F9: =SUM('Bảng 2'!#REF!) -> #REF!
A10: Tổng mức đầu tư của dự án | C10: =TH!O35 -> 7627000000 | E10: =C10-KHDT!C28 -> #REF! | F10: =SUM(F7:F9) -> #REF!

Sheet TMĐT
A1: TỔNG MỨC ĐẦU TƯ
A2: DỰ ÁN: CHỐNG SẠT LỞ VÀ GIA CỐ BỜ TẢ SÔNG HỒNG QUANG HUYỆN THANH MIỆN - ĐOẠN TỪ K5+800 ĐẾN K9+750
A4: STT | B4: Nội dung công việc | C4: Tỷ lệ | D4: Hệ số | E4: Cách tính | F4: Chi phí trước thuế | G4: Thuế GTGT | H4: Chi phí sau thuế | I4: Ghi chú
A5: I | B5: CHI PHÍ ĐỀN BÙ GPMB (dự kiến) | H5: =+F5 -> 0 | I5: Gđb
A6: II | B6: CHI PHÍ XÂY DỰNG (Gxd) | F6: =+F7 -> 3.9664942e+10 | G6: =+G7 -> 3.1731953e+09 | H6: =+H7 -> 42838137000 | I6: Gxd | J6: 40150000000 | K6: =+J6-H6 -> -2688137000
A7: 1 | B7: Phần xây dựng công trình thủy lợi | E7: theo DT | F7: =+'[365]TH dự toán công trình'!D11/1.08 -> 3.9664942e+10 | G7: =F7*0.08 -> 3.1731953e+09 | H7: =F7+G7 -> 42838137000 | I7: Gxd1
A8: III | B8: Chi phÝ qu¶n lý dù ¸n | F8: =+F9 -> 1.0213722e+09 | G8: =+G9 -> 0 | H8: =ROUND(H9,-3) -> 1021372000 | I8: Gqlda
A9: 1.1 | B9: Chi phí quản lý dự án (PL VIII của TT12/2021/TT-BXD) - Công trình Thủy lợi | C9: =ROUND(2.769%-(2.769%-2.473%)*(($F$6)/10^9-20)/(50-20),5) -> 0.02575 | E9: Gxd trước thuế x tỷ lệ | F9: =+C9*F6 -> 1.0213722e+09 | H9: =+F9 -> 1.0213722e+09
A10: IV | B10: Chi phÝ t­ vÊn ®Çu t­ x©y dùng | F10: =+F11+F17 -> 3.5125079e+09 | G10: =+G11+G17 -> 2.7243593e+08 | H10: =ROUND(H11+H17,-3) -> 3784944000 | I10: Gtv
A11: 1 | B11: Chi phí tư vấn giai đoạn lập BCNCKT | F11: =ROUND(SUM(F12:F16),-3) -> 474856000 | G11: =ROUND(SUM(G12:G16),-3) -> 37216000 | H11: =ROUND(SUM(H12:H16),-3) -> 512072000 | I11: Gtv1
A12: 1.1 | B12: Chi phí khảo sát địa hình giai đoạn lập BCNCKT | E12: Theo QĐ số 243/QĐ-BQLDA ngày 15/11/2023 | F12: =136593000/1.08 -> 1.26475e+08 | G12: =F12*0.08 -> 10118000 | H12: =+F12+G12 -> 1.36593e+08 | I12: Gtv1.1
A13: 1.2 | B13: Lập báo cáo nghiên cứu khả thi (PL VIII của TT12/2021/TT-BXD) | E13: Theo QĐ số 243/QĐ-BQLDA ngày 15/11/2023 | F13: =306388000/1.08 -> 2.8369259e+08 | G13: =F13*0.08 -> 22695407 | H13: =+G13+F13 -> 306388000 | I13: Gtv1.2 | J13: 0.745 | K13: =+J13*F6/100 -> 2.9550382e+08
A14: 1.3 | B14: Chi phí thẩm tra báo cáo nghiên cứu khả thi | E14: Theo QĐ số 243/QĐ-BQLDA ngày 15/11/2023 | F14: =59431000/1.08 -> 55028704 | G14: =F14*0.08 -> 4402296.3 | H14: =+G14+F14 -> 59431000 | I14: Gtv1.3 | N14: b | O14: a
A15: 1.5 | B15: Chi phí lập nhiệm vụ khảo sát xây dựng | E15: Theo QĐ số 243/QĐ-BQLDA ngày 15/11/2023 | F15: 4098000 | H15: =ROUND(G15+F15,-3) -> 4098000 | I15: Gtv1.5 | N15: 50 | O15: 20 | P15: =+F6/1000000000 -> 39.664942
A16: 1.6 | B16: Chi phí giám sát công tác khảo sát xây dựng (PL VIII của TT12/2021/TT-BXD) | E16: Theo QĐ số 243/QĐ-BQLDA ngày 15/11/2023 | F16: 5562000 | H16: =ROUND(G16+F16,-3) -> 5562000 | I16: Gtv1.6 | K16: Cxd | L16: Nt | M16: Ki | N16: 2.31 | O16: 2.76 | P16: =+N16-(N16-O16)*(P15-N15)/(O15-N15) -> 2.4650259
A17: 2 | B17: Chi phí tư vấn giai đoạn lập TKBVTC | F17: =SUM(F18:F33) -> 3.0376519e+09 | G17: =SUM(G18:G33) -> 2.3521993e+08 | H17: =ROUND(SUM(H18:H33),-3) -> 3272872000 | I17: Gtv2
A18: 2.1 | B18: Chi phí khảo sát địa hình giai đoạn TKBVTC | E18: Tạm tính | F18: =150000000/1.08 -> 1.3888889e+08 | G18: =F18*0.08 -> 11111111 | H18: =+F18+G18 -> 1.5e+08 | I18: Gtv2.1
A19: 2.2 | B19: Chi phí khảo sát địa chất giai đoạn TKBVTC | E19: Tạm tính | F19: =670657000/1.08 -> 6.209787e+08 | G19: =F19*0.08 -> 49678296 | H19: =+F19+G19 -> 6.70657e+08 | I19: Gtv2.2
A20: 2.3 | B20: Chi phí thiết kế - Công trình Thủy lợi | C20: =+P16/100 -> 0.024650259 | E20: Gxd trước thuế x tỷ lệ | F20: =+C20*F6 -> 9.7775108e+08 | G20: =F20*0.08 -> 78220086 | H20: =+F20+G20 -> 1.0559712e+09 | I20: Gtv2.3
A21: 2.4 | B21: Chi phí lập nhiệm vụ khảo sát xây dựng | C21: 0.03 | E21: Gks trước thuế x tỷ lệ | F21: =+C21*(F18+F19) -> 22796028 | H21: =+F21+G21 -> 22796028 | I21: Gtv2.4
A22: 2.5 | B22: Chi phí giám sát công tác khảo sát xây dựng (PL VIII của TT12/2021/TT-BXD) | C22: 0.04072 | E22: Gks trước thuế x tỷ lệ | F22: =+C22*(F18+F19) -> 30941808 | H22: =+F22+G22 -> 30941808 | I22: Gtv2.5 | K22: =+H18+H19+H20 -> 1.8766282e+09
A23: 2.6 | B23: Chi phí giám sát thi công xây dựng công trình (PL VIII của TT12/2021/TT-BXD) - Công trình Thủy lợi | C23: =ROUND(2.292%-(2.292%-2.075%)*(($F$6)/10^9-20)/(50-20),5) -> 0.0215 | E23: Gxd trước thuế x tỷ lệ | F23: =+C23*F6 -> 8.5279625e+08 | G23: =F23*0.08 -> 68223700 | H23: =+F23+G23 -> 9.2101995e+08 | I23: Gtv2.6
A24: 2.7 | B24: Chi phí lập hồ sơ mời thầu, hồ sơ yêu cầu + đánh giá hồ sơ dự thầu, hồ sơ đề xuất gói thầu tư vấn thiết kế giai đoạn TKBVTC (PL VIII của TT12/2021/TT-BXD) | C24: 0.007139 | E24: (Gtv2.1+Gtv2.2+Gtv2.3) trước thuế x tỷ lệ | F24: =+C24*(F18+F19+F20) -> 12404860 | G24: =F24*0.08 -> 992388.77 | H24: =+F24+G24 -> 13397248 | I24: Gtv2.7 | N24: 3 | O24: 1 | P24: =+(H18+H19+H20)/1000000000 -> 1.8766282
A25: 2.8 | B25: Chi phí thẩm định hồ sơ mời thầu, hồ sơ yêu cầu và chi phí thẩm định kết quả lựa chọn nhà thầu gói thầu tư vấn thiết kế (Nghị định 63/2014/NĐ-CP) | C25: 0.001 | E25: Giá trị tối thiểu | F25: 2000000 | H25: =+F25+G25 -> 2000000 | I25: Gtv2.8 | J25: =+C25*(F20+F18) -> 1116640 | N25: 0.583 | O25: 0.816 | P25: =+N25-(N25-O25)*(P24-N24)/(O24-N24) -> 0.71387282
A26: 2.9 | B26: Chi phí lập hồ sơ mời thầu, đánh giá hồ sơ dự thầu thi công xây dựng(PL VIII của TT12/2021/TT-BXD) - Công trình Thủy lợi | C26: =ROUND(0.302%-(0.302%-0.166%)*(($F$6)/10^9-20)/(50-20),5) -> 0.00213 | E26: Gxd trước thuế x tỷ lệ | F26: =$F$6*C26 -> 84486326 | G26: =F26*0.08 -> 6758906.1 | H26: =+F26+G26 -> 91245232 | I26: Gtv2.9
A27: 2.10 | B27: Chi phí thẩm định hồ sơ mời thầu, hồ sơ yêu cầu và chi phí thẩm định kết quả lựa chọn nhà thầu gói thầu thi công (Nghị định 63/2014/NĐ-CP) | C27: 0.001 | E27: Gxd trước thuế x tỷ lệ | F27: =+C27*F6 -> 39664942 | H27: =+F27+G27 -> 39664942 | I27: Gtv2.10 | N27: 50 | O27: 20 | P27: =+F23/1000000000 -> 0.85279625
A28: 2.11 | B28: Chi phí lập hồ sơ mời thầu, hồ sơ yêu cầu + đánh giá hồ sơ dự thầu, hồ sơ đề xuất gói thầu tư vấn giám sát (PL VIII của TT12/2021/TT-BXD) | C28: 0.00816 | E28: Gtv2.6 trước thuế x tỷ lệ | F28: =+C28*(F23) -> 6958817.4 | G28: =F28*0.08 -> 556705.39 | H28: =+F28+G28 -> 7515522.8 | I28: Gtv2.11 | N28: 0.176 | O28: 0.311 | P28: =+N28-(N28-O28)*(P27-N27)/(O27-N27) -> 0.39716242
A29: 2.12 | B29: Chi phí thẩm định hồ sơ mời thầu, hồ sơ yêu cầu và chi phí thẩm định kết quả lựa chọn nhà thầu gói thầu tư vấn giám sát (Nghị định 63/2014/NĐ-CP) | C29: 0.001 | E29: Giá trị tối thiểu | F29: 2000000 | H29: =+F29+G29 -> 2000000 | I29: Gtv2.12
A30: 2.13 | B30: Chi phí thẩm tra thiết kế xây dựng (PL VIII của TT12/2021/TT-BXD) - Công trình Thủy lợi | C30: =ROUND(0.163%-(0.163%-0.125%)*(($F$6)/10^9-20)/(50-20),5) -> 0.00138 | E30: Gxd trước thuế x tỷ lệ | F30: =$F$6*C30 -> 54737619 | G30: =F30*0.08 -> 4379009.6 | H30: =+ROUND(F30+G30,-3) -> 59117000 | I30: Gtv2.13
A31: 2.14 | B31: Chi phí thẩm tra dự toán xây dựng (PL VIII của TT12/2021/TT-BXD) - Công trình Thủy lợi | C31: =ROUND(0.158%-(0.158%-0.119%)*(($F$6)/10^9-20)/(50-20),5) -> 0.00132 | E31: Gxd trước thuế x tỷ lệ | F31: =$F$6*C31 -> 52357723 | G31: =F31*0.08 -> 4188617.8 | H31: =+ROUND(F31+G31,-3) -> 56546000 | I31: Gtv2.14 | L31: 50 | M31: 15 | N31: =+F6/1000000000 -> 39.664942
A32: 2.15 | B32: Tư vấn đăng kí môi trường | E32: Tạm tính | F32: =100000000/1.08 -> 92592593 | G32: =F32*0.08 -> 7407407.4 | H32: =+G32+F32 -> 1e+08 | I32: Gtv2.15 | L32: 0.076 | M32: 0.117 | N32: =+L32-(L32-M32)*(N31-L31)/(M31-L31) -> 0.088106783
A33: 2.16 | B33: Chi phí nén ép cọc BTCT | E33: Tạm tính | F33: =+H33/1.08 -> 46296296 | G33: =F33*0.08 -> 3703703.7 | H33: 50000000 | I33: Gtv2.16
A34: 21 | B34: Chi phí kiểm định chất lượng công trình xây dựng | E34: =+E33 -> Tạm tính | F34: =+H34/1.1 -> 0 | G34: =+F34*10% -> 0 | I34: Gtv2.17
A35: V | B35: Chi phÝ kh¸c | F35: =SUM(F36:F44) -> 8.8684044e+08 | G35: =SUM(G36:G44) -> 41320069 | H35: =SUM(H36:H44) -> 928161000
A36: 1 | B36: Bảo hiểm công trình (TT 50/2021/TT-BTC) | C36: 0.005 | E36: Gxd trước thuế x tỷ lệ | F36: =+C36*$F$6 -> 1.9832471e+08 | G36: =+F36*8% -> 15865977 | H36: =ROUND(G36+F36,-3) -> 214191000
A37: 2 | B37: Phí thẩm định thiết kế xây dựng triển khai sau thiết kế cơ sở (TT 27/2023/TT-BTC+TT44/2023/TT-BTC) - Công trình Thủy lợi | C37: =ROUND(0.121%-(0.121%-0.08%)*(($F$6)/10^9-15)/(50-15),5) -> 0.00092 | D37: 0.5 | E37: Gxd trước thuế x tỷ lệ | F37: =+C37*$F$6*D37 -> 18245873 | H37: =ROUND(G37+F37,-3) -> 18246000 | K37: 100 | L37: 50 | M37: =50132400000/1000000000 -> 50.1324
A38: 3 | B38: Phí thẩm định dự toán xây dựng(TT 27/2023/TT-BTC +TT44/2023/TT-BTC) - Công trình Thủy lợi | C38: =ROUND(0.117%-(0.117%-0.076%)*(($F$6)/10^9-15)/(50-15),5) -> 0.00088 | D38: 0.5 | E38: Gxd trước thuế x tỷ lệ | F38: =+C38*$F$6 -> 34905149 | H38: =ROUND(G38+F38,-3) -> 34905000 | K38: 0.0125 | L38: 0.015 | M38: =+K38-(K38-L38)*(M37-K37)/(L37-K37) -> 0.01499338
A39: 4 | B39: Phí thẩm định dự án TT28/2023/TT-BTC | C39: 0.00015 | D39: 0.5 | E39: 15%*Gtv1.3 | F39: =+C39*K48*D39 -> 3759725.9 | H39: =ROUND(G39+F39,-3) -> 3760000
A40: 5 | B40: Chi phí kiểm tra công tác nghiệm thu công trình xây dựng (Thông tư 10/2021/TT-BXD) | C40: 0.2 | E40: 20%*Ggs | F40: =+C40*F23 -> 1.7055925e+08 | H40: =ROUND(G40+F40,-3) -> 170559000
A41: 6 | B41: Chi phí điều tiết đảm bảo ATGT | E41: Tạm tính | F41: =50000000/1.08 -> 46296296 | G41: =F41*0.08 -> 3703703.7 | H41: =ROUND(G41+F41,-3) -> 50000000
...

Sheet PL Tờ trình
A1: BẢNG TÀI LIỆU KÈM THEO VĂN BẢN TRÌNH DUYỆT
A2: ='Bảng 1'!A2:E2 -> (kèm theo Tờ trình số /TTr-BQLDA ngày tháng năm 2024 của Ban Quản lý dự án đầu tư xây dựng huyện Thanh Miện)
A4: STT | B4: Nội dung | C4: Ghi chú
A5: 1 | B5: Nghị quyết số 55/NQ-HĐND ngày 21 tháng 12 năm 2023 của Hội đồng nhân dân huyện Thanh Miện về việc quyết định chủ trương đầu tư dự án: Đầu tư xây dựng các hạng mục phụ trợ Trường mầm non Tân Trào; | C5: Bản chụp
A6: 2 | B6: Quyết định số 296/QĐ-BQLDA ngày 27 tháng 12 năm 2023 của Giám đốc Ban Quản lý dự án đầu tư xây dựng huyện Thanh Miện về việc phê duyệt nhiệm vụ khảo sát, thiết kế xây dựng; dự toán một số chi phí bước lập Báo cáo kinh tế - kỹ thuật đầu tư xây dựng dự án: Đầu tư xây dựng các hạng mục phụ trợ Trường mầm non Tân Trào; | C6: Bản chụp
A7: 3 | B7: Quyết định số 311/QĐ-BQLDA ngày 29 tháng 12 năm 2023 của Giám đốc Ban Quản lý dự án đầu tư xây dựng huyện Thanh Miện về việc phê duyệt Kế hoạch lựa chọn nhà thầu các gói thầu giai đoạn chuẩn bị đầu tư dự án: Đầu tư xây dựng các hạng mục phụ trợ Trường mầm non Tân Trào; | C7: Bản chụp
A8: 4 | B8: Quyết định số 12/QĐ-BQLDA ngày 03 tháng 01 năm 2024 của Giám đốc Ban Quản lý dự án đầu tư xây dựng huyện Thanh Miện về việc phê duyệt kết quả chỉ định thầu gói thầu số 01: Tư vấn khảo sát, lập Báo cáo kinh tế - kỹ thuật dự án đầu tư xây dựng các hạng mục phụ trợ Trường mầm non Tân Trào; | C8: Bản chụp
A9: 5 | B9: Quyết định số 13/QĐ-BQLDA ngày 03 tháng 01 năm 2024 của Giám đốc Ban Quản lý dự án đầu tư xây dựng huyện Thanh Miện về việc phê duyệt kết quả chỉ định thầu gói thầu số 02: Tư vấn thẩm tra Báo cáo kinh tế - kỹ thuật dự án đầu tư xây dựng các hạng mục phụ trợ Trường mầm non Tân Trào; | C9: Bản chụp
A10: 6 | B10: Quyết định số 33/QĐ-BQLDA ngày 16 tháng 01 năm 2024 của Giám đốc Ban Quản lý dự án đầu tư xây dựng huyện Thanh Miện về việc phê duyệt kết quả chỉ định thầu gói thầu số 03: Thẩm định giá vật tư, thiết bị dự án đầu tư xây dựng các hạng mục phụ trợ Trường mầm non Tân Trào; | C10: Bản chụp
A11: 7 | B11: Quyết định số 979/QĐ-UBND ngày 05 tháng 4 năm 2024 của Chủ tịch Ủy ban nhân dân huyện Thanh Miện về việc phê duyệt Báo cáo kinh tế - kỹ thuật dự án: Đầu tư xây dựng các hạng mục phụ trợ Trường mầm non Tân Trào; | C11: Bản chụp

Sheet TH
A1: BẢNG TỔNG MỨC ĐẦU TƯ
A2: =[366]BIA!B63 -> CÔNG TRÌNH: ĐẦU TƯ XÂY DỰNG CÁC HẠNG MỤC PHỤ TRỢ TRƯỜNG MẦM NON TÂN TRÀO
O3: Đơn vị tính : đồng
A4: STT | B4: Khoản mục chi phí | C4: Ký hiệu | D4: Định mức | E4: Hệ số | F4: Cách tính | M4: Chi phí trước thuế | N4: Thuế giá trị gia tăng | O4: Chi phí sau thuế
A5: I | B5: CHI PHÍ XÂY DỰNG | C5: Gxd | F5: =C6 -> Gxd1 | G5: : | I5: =C11 -> Gxd6 | M5: =SUBTOTAL(9,M6:M11) -> 5.8619182e+09 | N5: =SUBTOTAL(9,N6:N11) -> 5.8619182e+08 | O5: =ROUND(SUBTOTAL(9,O6:O11),-3) -> 6448110000 | P5: 6448110000
A6: 1 | B6: Nhà vòm | C6: Gxd1 | F6: Bảng TH giá dự toán hạng mục | M6: ='[367]TH giá dự thầu'!$D$5/1.1 -> 1.427563e+09 | N6: =10%*M6 -> 1.427563e+08 | O6: =M6+N6 -> 1570319332
A7: 2 | B7: Cổng vào | C7: Gxd2 | F7: Bảng TH giá dự toán hạng mục | M7: ='[367]TH giá dự thầu'!$D$6/1.1 -> 343548670 | N7: =10%*M7 -> 34354867 | O7: =M7+N7 -> 377903537
A8: 3 | B8: Sân, bồn hoa | C8: Gxd3 | F8: Bảng TH giá dự toán hạng mục | M8: ='[367]TH giá dự thầu'!$D$7/1.1 -> 2.9001008e+09 | N8: =10%*M8 -> 2.9001008e+08 | O8: =M8+N8 -> 3190110829
A9: 4 | B9: Mương, cống, đường bê tông | C9: Gxd4 | F9: Bảng TH giá dự toán hạng mục | M9: ='[367]TH giá dự thầu'!$D$8/1.1 -> 6.489748e+08 | N9: =10%*M9 -> 64897480 | O9: =M9+N9 -> 7.1387228e+08
A10: 5 | B10: Hạ tầng thoát nước | C10: Gxd5 | F10: Bảng TH giá dự toán hạng mục | M10: ='[367]TH giá dự thầu'!$D$9/1.1 -> 1.5313527e+08 | N10: =10%*M10 -> 15313527 | O10: =M10+N10 -> 168448801
A11: 6 | B11: Hạ tầng phần điện | C11: Gxd6 | F11: Bảng TH giá dự toán hạng mục | M11: ='[367]TH giá dự thầu'!$D$10/1.1 -> 3.8859567e+08 | N11: =10%*M11 -> 38859567 | O11: =M11+N11 -> 4.2745524e+08
A12: II | B12: CHI PHÍ TƯ VẤN QUẢN LÝ DỰ ÁN | C12: Gqlda | F12: =C13 -> Gqlda1 | G12: : | I12: =C13 -> Gqlda1 | M12: =SUBTOTAL(9,M13:M13) -> 2.020017e+08 | N12: =SUBTOTAL(9,N13:N13) -> 0 | O12: =ROUND(SUBTOTAL(9,O13:O13),-3) -> 202002000 | P12: 202002000
A13: 1 | B13: Chi phí quản lý dự án (Thông tư 12/2021/TT-BXD) | C13: Gqlda1 | D13: ='[366]TT12.2021'!O884% -> 0.03446 | F13: =D13 -> 0.03446 | G13: x | I13: =$C$5 -> Gxd | M13: =D13*($M$5) -> 2.020017e+08 | O13: =ROUND((N13+M13),-3) -> 202002000
A14: III | B14: CHI PHÍ TƯ VẤN | C14: Gtv | F14: =C15 -> Gtv1 | G14: : | I14: =C24 -> Gtv8 | M14: =SUBTOTAL(9,M15:M25) -> 5.346172e+08 | N14: =SUBTOTAL(9,N15:N25) -> 53461720 | O14: =ROUND(SUBTOTAL(9,O15:O25),-3) -> 588078000 | P14: 588078000
A15: 1 | B15: Chi phí khảo sát địa hình | C15: Gtv1 | F15: Dự toán chi tiết | M15: ='[367]TH giá dự thầu'!$D$11/1.1 -> 9517663.6 | N15: =M15*10% -> 951766.36 | O15: =ROUND((N15+M15),-3) -> 10469000
A16: 2 | B16: Chi phí lập nhiệm vụ khảo sát địa hình | C16: Gtv2 | D16: 0.03 | F16: =D16 -> 0.03 | G16: x | I16: =$C$15 -> Gtv1 | M16: =D16*SUM($M$15) -> 285529.91 | N16: =M16*10% -> 28552.991 | O16: =ROUND((N16+M16),-3) -> 314000
A17: 3 | B17: Chi phí lập báo cáo kinh tế kỹ thuật (Thông tư 12/2021/TT-BXD) | C17: Gtv3 | D17: ='[366]TT12.2021'!G920% -> 0.04342 | F17: =D17 -> 0.04342 | G17: x | I17: =$C$5 -> Gxd | M17: =D17*($M$5) -> 2.5452449e+08 | N17: =M17*10% -> 25452449 | O17: =ROUND((N17+M17),-3) -> 279977000
A18: 4 | B18: Chi phí thẩm tra báo cáo kinh tế kỹ thuật(Thông tư 12/2021/TT-BXD) | C18: Gtv4 | F18: Theo Quyết định số: 13/QĐ-BQLDA ngày 3/01/2024 | M18: =O18/1.1 -> 35223636 | N18: =M18*10% -> 3522363.6 | O18: 38746000
A19: 4.1 | B19: Chi phí thẩm tra kế bản vẽ thi công (Thông tư 12/2021/TT-BXD) | C19: Gtv4.1 | D19: ='[366]TT12.2021'!N1028% -> 0.00258 | E19: 1.2 | F19: =D19 -> 0.00258 | G19: x | I19: =E19 -> 1.2 | J19: x | K19: =$C$5 -> Gxd | N19: =M19*10% -> 0 | O19: =ROUND((N19+M19),-3) -> 0
A20: 4.2 | B20: Chi phí thẩm tra dự toán (Thông tư 12/2021/TT-BXD) | C20: Gtv4.2 | D20: ='[366]TT12.2021'!N1040% -> 0.0025 | E20: 1.2 | F20: =D20 -> 0.0025 | G20: x | I20: =E20 -> 1.2 | J20: x | K20: =$C$5 -> Gxd | N20: =M20*10% -> 0 | O20: =ROUND((N20+M20),-3) -> 0
A21: 5 | B21: Chi phí lập hồ sơ mời thầu, đánh giá hồ sơ dự thầu, gói thầu thi công xây dựng (Thông tư 12/2021/TT-BXD) | C21: Gtv5 | D21: ='[366]TT12.2021'!K1076% -> 0.00432 | F21: =D21 -> 0.00432 | G21: x | I21: =$C$5 -> Gxd | M21: =D21*$M$5 -> 25323487 | N21: =M21*10% -> 2532348.7 | O21: =ROUND((N21+M21),-3) -> 27856000
A22: 6 | B22: Chi phí thẩm định hồ sơ mời thầu thi công xây dựng (Nghị định 24/2024/NĐ-CP) | C22: Gtv6 | D22: 0.001 | F22: =D22 -> 0.001 | G22: x | I22: =$C$5 -> Gxd | M22: =ROUND(IF($M$5*D22<2000000,2000000,IF($M$5*D22>60000000,60000000,$M$5*D22)),0) -> 5861918 | N22: =M22*10% -> 586191.8 | O22: =ROUND((N22+M22),-3) -> 6448000
A23: 7 | B23: Chi phí thẩm định kết quả lựa chọn nhà thầu thi công xây dựng (Nghị định 24/2024/NĐ-CP) | C23: Gtv7 | D23: 0.001 | F23: =D23 -> 0.001 | G23: x | I23: =$C$5 -> Gxd | M23: =ROUND(IF($M$5*D23<3000000,3000000,IF($M$5*D23>60000000,60000000,$M$5*D23)),0) -> 5861918 | N23: =M23*10% -> 586191.8 | O23: =ROUND((N23+M23),-3) -> 6448000
A24: 8 | B24: Chi phí giám sát thi công xây dựng (Thông tư 12/2021/TT-BXD) | C24: Gtv8 | D24: ='[366]TT12.2021'!N1100% -> 0.03285 | F24: =D24 -> 0.03285 | G24: x | I24: =$C$5 -> Gxd | M24: =D24*$M$5 -> 1.9256401e+08 | N24: =M24*10% -> 19256401 | O24: =ROUND((N24+M24),-3) -> 211820000
A25: 9 | B25: Chi phí thẩm định giá vật tư, thiết bị không có trong công bố giá | C25: Gtv9 | F25: Hợp đồng thẩm định giá số 2403168/HĐTĐG-TMC | M25: =O25/1.1 -> 5454545.5 | N25: =M25*10% -> 545454.55 | O25: 6000000
A26: IV | B26: CHI PHÍ KHÁC | C26: Gk | F26: =C27 -> Gk1 | G26: : | I26: =C32 -> Gk7 | M26: =SUBTOTAL(9,M27:M32) -> 1.2289941e+08 | N26: =SUBTOTAL(9,N27:N32) -> 6554791.5 | O26: =ROUND(SUBTOTAL(9,O27:O32),-3) -> 129454000 | P26: 129454000
A27: 1 | B27: Chi phí bảo hiểm công trình (Phụ lục III - Nghị định 67/2023/NĐ-CP: Công trình dân dụng - Công trình giáo dục cấp III trở lên, không có tầng hầm) | C27: Gk1 | D27: 0.0008 | F27: =D27 -> 0.0008 | G27: x | I27: =$C$5 -> Gxd | M27: =D27*($M$5) -> 4689534.6 | N27: =10%*M27 -> 468953.46 | O27: =ROUND((N27+M27),-3) -> 5158000
A28: 2 | B28: Chi phí đăng tải thông tin đấu thầu (Thông tư 06/2021/TT-BKHĐT) | C28: Gk2 | M28: =300000 -> 300000 | N28: =10%*M28 -> 30000 | O28: =ROUND((N28+M28),-3) -> 330000
A29: 3 | B29: Chi phí thẩm định báo cáo kinh tế kỹ thuật (Thông tư 28/2023/TT-BTC) | C29: Gk3 | D29: ='[366]TT12.2021'!M1187/100 -> 0.00019 | E29: 0.5 | F29: =D29 -> 0.00019 | G29: x | I29: =E29 -> 0.5 | J29: x | K29: =$C$35 -> Gtmđt | M29: =IF(D29*E29*$P$35<500000,500000,IF(D29*E29*$P$35>150000000,150000000,D29*E29*$P$35)) -> 724565 | O29: =ROUND((N29+M29),-3) -> 725000
A30: 5 | B30: Chi phí kiểm tra công tác nghiệm thu (Điều 24 Nghị định 06/2021/NĐ-CP và Điều 16 Thông tư 10/2021/TT-BXD) | C30: Gk5 | D30: 0.2 | F30: =D30 -> 0.2 | G30: x | I30: =C24 -> Gtv8 | M30: =D30*$M$24 -> 38512803 | O30: =ROUND((N30+M30),-3) -> 38513000
A31: 6 | B31: Chi phí kiểm toán độc lập (Nghị định 99/2021/NĐ-CP | C31: Gk6 | D31: ='[366]TT12.2021'!J1149/100 -> 0.00794 | F31: =D31 -> 0.00794 | G31: x | I31: =$C$35 -> Gtmđt | M31: =D31*$P$35 -> 60558380 | N31: =10%*M31 -> 6055838 | O31: =ROUND((N31+M31),-3) -> 66614000
A32: 7 | B32: Chi phí thẩm tra phê duyệt quyết toán (Nghị định 99/2021/NĐ-CP) | C32: Gk7 | D32: ='[366]TT12.2021'!J1142/100 -> 0.00475 | E32: 0.5 | F32: =D32 -> 0.00475 | G32: x | I32: =E32 -> 0.5 | K32: =$C$35 -> Gtmđt | M32: =D32*E32*$P$35 -> 18114125 | O32: =ROUND((N32+M32),-3) -> 18114000
A33: V | B33: CHI PHÍ DỰ PHÒNG | C33: Gdp | F33: =C34 -> Gdp1 | G33: : | I33: =C34 -> Gdp1 | O33: =ROUND(SUBTOTAL(9,O34:O34),-3) -> 259356000 | P33: 259356000
A34: 1 | B34: Chi phí dự phòng khối lượng phát sinh | C34: Gdp1 | O34: =ROUND(P35-($O$5+$O$12+$O$14+$O$26),-3) -> 259356000
B35: TỔNG MỨC ĐẦU TƯ | C35: Gtmđt | F35: Gxd+Gqlda+Gtv+Gk+Gdp | O35: =$O$5+$O$12+$O$14+$O$26+$O$33 -> 7627000000 | P35: 7627000000
B36: Bằng chữ: Bảy tỷ, sáu trăm hai mươi bảy triệu đồng./.

Sheet KHDT
A1: TỔNG HỢP KẾ HOẠCH ĐẤU THẦU
C2: Đơn vị: đồng./.
A3: TT | B3: Nội dung | C3: Giá trị
A4: I | B4: Phần công việc thuộc kế hoạch lựa chọn nhà thầu | C4: =SUM(C5:C10) -> #REF! | D4: Điểm c Khoản 3 Điều 4 TT 10/2015/TT-BKHĐT | E4: Bảng 3'!Print_Area
A5: 1 | B5: Gói thầu số 01: Tư vấn lập hồ sơ mời thầu, đánh giá hồ sơ dự thầu thi công xây dựng | C5: =#REF! -> #REF!
A6: 2 | B6: Gói thầu số 02: Tư vấn thẩm định hồ sơ mời thầu, thẩm định kết quả lựa chọn nhà thầu | C6: =#REF!+#REF! -> #REF!
A7: 3 | B7: Gói thầu số 03: Tư vấn giám sát thi công xây dựng | C7: =#REF! -> #REF!
A8: 4 | B8: Gói thầu số 4: Chi phí bảo hiểm công trình | C8: =#REF! -> #REF!
A9: 5 | B9: Gói thầu số 5: Tư vấn kiểm toán | C9: =#REF! -> #REF!
A10: 6 | B10: Gói thầu số 6: Thi công xây dựng | C10: =#REF! -> #REF!
A12: II | B12: Phần công việc đã thực hiện | C12: =SUM(C13:C16) -> #REF! | D12: Điểm a Khoản 3 Điều 4 TT 10/2015/TT-BKHĐT | E12: Bảng 1'!Print_Area
A13: 1 | B13: Tư vấn khảo sát, lập báo cáo kinh tế kỹ thuật đầu tư xây dựng công trình: Tu bổ, tôn tạo Đền tưởng niệm Liệt sỹ huyện | C13: =#REF! -> #REF!
A14: 2 | B14: Tư vấn thẩm tra thiết kế bản vẽ thi công và dự toán công trình: Tu bổ, tôn tạo Đền tưởng niệm Liệt sỹ huyện | C14: =#REF!+#REF! -> #REF!
A15: 4 | B15: Thẩm định giá Thiết bị vật liệu xây dựng công trình tu bổ, tôn tạo Đền tưởng niệm liệt sỹ huyện | C15: =#REF! -> #REF!
A16: 6 | B16: =#REF! -> #REF! | C16: =#REF! -> #REF!
A17: III | B17: Phần công việc không áp dụng được một trong các hình thức lựa chọn nhà thầu | C17: =SUM(C18:C23) -> #REF! | D17: Điểm b Khoản 3 Điều 4 TT 10/2015/TT-BKHĐT | E17: Bảng 2'!Print_Area
A18: 1 | B18: =#REF! -> #REF! | C18: =#REF! -> #REF!
A19: 2 | B19: =#REF! -> #REF! | C19: =#REF! -> #REF!
A20: 3 | B20: =#REF! -> #REF! | C20: =#REF! -> #REF!
A22: 4 | B22: =#REF! -> #REF! | C22: =#REF! -> #REF!
A23: 5 | B23: =#REF! -> #REF! | C23: =#REF! -> #REF!
A24: IV | B24: Phần công việc chưa đủ điều kiện lập kế hoạch lựa chọn nhà thầu | C24: =C25+C26 -> 0 | D24: Điểm d Khoản 3 Điều 4 TT 10/2015/TT-BKHĐT | E24: Bảng 4'!Print_Area
A28: V | B28: Tổng cộng | C28: =C4+C12+C17+C24 -> #REF! | E28: Bảng 5'!Print_Area
C30: =C28-C29 -> #REF!

Sheet TMDT
A1: BẢNG TỔNG MỨC ĐẦU TƯ XÂY DỰNG
B2: Dự án: Cải tạo, nâng cấp đường huyện 195, đoạn từ Km0 - Km4+300, huyện Thanh Miện
B3: Hạng mục: Nền, mặt đường, thoát nước, ATGT và GPMB
B4: Chủ đầu tư: Ban Quản lý dự án đầu tư xây dựng huyện Thanh Miện
B5: Tư vấn lập dự án: Liên danh: Công ty Cổ phần đầu tư xây dựng Long Thành HD - Công ty Cổ phần tư vấn khảo sát và kiểm định xây dựng Đông Phương
B6: Địa điểm xây dựng: Xã Lê Hồng, xã Đoàn Kết và xã Hồng Quang, huyện Thanh Miện
B7: Thời gian thực hiện dự án: Năm 2022-2024
B8: Nguồn vốn đầu tư: Ngân sách huyện
B9: Loại, cấp công trình: Công trình giao thông, cấp III
G10: Đơn vị tính: đồng
A11: TT | B11: NỘI DUNG CHI PHÍ | C11: DIỄN GIẢI CÁCH TÍNH | F11: GIÁ TRỊ TRƯỚC THUẾ (ĐỒNG) | G11: THUẾ GTGT (ĐỒNG) | H11: GIÁ TRỊ SAU THUẾ (ĐỒNG) | I11: KÝ HIỆU
A12: I | B12: CHI PHÍ BỒI THƯỜNG GPMB, HỖ TRỢ TĐC | F12: =F13 -> 1.0552045e+09 | G12: =G13 -> 1.0552045e+08 | H12: =H13 -> 1160725000 | I12: GGPMB
A13: 1 | B13: Di chuyển đường điện trung, hạ thế | C13: Dự toán chi tiết (có thiết kế riêng) | F13: =H13/1.1 -> 1.0552045e+09 | G13: =F13*0.1 -> 1.0552045e+08 | H13: ='Tổng mức đầu tư'!J80 -> 1160725000 | J13: tính 2 lân dự phòng (đã bỏ)
A14: 1.1 | B14: Chi phí khảo sát, lập thiết kế BVTC hạng mục di chuyển đường điện trung, hạ thế | D14: - | F14: =H14/1.1 -> 94588002 | G14: =F14*0.1 -> 9458800.2 | H14: ='[368]Tổng mức đầu tư'!$J$23+'[368]Tổng mức đầu tư'!$J$27 -> 104046802
A15: 1.2 | B15: Chi phí thẩm tra thiết kế BVTC và dự toán hạng mục di chuyển đường điện trung, hạ thế | D15: - | F15: =H15/1.1 -> 4820760.9 | G15: =F15*0.1 -> 482076.09 | H15: ='[368]Tổng mức đầu tư'!$J$34+'[368]Tổng mức đầu tư'!$J$35 -> 5302837
A16: 1.3 | B16: Chi phí xây dựng hạng mục di chuyển đường điện trung, hạ thế | D16: - | F16: =H16/1.1 -> 8.4344579e+08 | G16: =F16*0.1 -> 84344579 | H16: =+'[368]Tổng mức đầu tư'!$J$12 -> 927790367
A17: 1.4 | B17: Chi phí khác | D17: - | F17: =H17/1.1 -> 1.1234999e+08 | G17: =F17*0.1 -> 11234999 | H17: =H13-H14-H15-H16 -> 123584994
A18: II | B18: CHI PHÍ XÂY DỰNG | F18: =SUM(F19:F27) -> 4.7346435e+10 | G18: =SUM(G19:G27) -> 4734643541 | H18: =SUBTOTAL(9,H19:H27) -> 52081079000 | I18: GXD | M18: =H18+#REF! -> #REF! | O18: =+H18 -> 52081079000
A19: 1 | B19: Nền đường, mặt đường, ATGT | C19: Dự toán chi tiết | F19: 2.8269028e+10 | G19: 2.8269028e+09 | H19: 31095931000 | O19: =O18/4300/7 -> 1730268.4
A20: =A19+1 -> 2 | B20: Block, vỉa hè | C20: Dự toán chi tiết | F20: 339968250 | G20: 33996825 | H20: 373965000
A21: =A20+1 -> 3 | B21: Thoát nước dọc | C21: Dự toán chi tiết | F21: 2.2369062e+09 | G21: 2.2369062e+08 | H21: 2460597000 | P21: 12.5 | Q21: 19 | R21: 16
A22: =A21+1 -> 4 | B22: Cống ngang đường | C22: Dự toán chi tiết | F22: 1.8469245e+09 | G22: 1.8469245e+08 | H22: 2031617000 | O22: 7 | P22: 16.97 | Q22: 16.62 | R22: =(P22+Q22)/2 -> 16.795
A23: =A22+1 -> 5 | B23: Cống hộp BTCT + cầu bản | C23: Dự toán chi tiết | F23: 7.6837322e+09 | G23: 7.6837322e+08 | H23: 8452105000 | M23: =+H28+H29+H78 -> 7495952000 | O23: 5 | P23: 12.12 | Q23: 11.87 | R23: =(P23+Q23)/2 -> 11.995
A24: =A23+1 -> 6 | B24: Tường chắn + kè mái taluy | C24: Dự toán chi tiết | F24: 3.9937872e+09 | G24: 3.9937872e+08 | H24: 4393166000
A25: =A24+1 -> 7 | B25: Mương xây hoàn trả | C25: Dự toán chi tiết | F25: 88020396 | G25: 8802039.6 | H25: 96822000
A26: =A25+1 -> 8 | B26: Đèn tín hiệu giao thông | C26: Dự toán chi tiết | F26: 1.7450344e+09 | G26: 174503441 | H26: 1919538000
A27: =A26+1 -> 9 | B27: Đèn chiếu sáng | C27: Dự toán chi tiết | F27: 1.1430344e+09 | G27: 1.1430344e+08 | H27: 1257338000
A28: III | B28: CHI PHÍ QUẢN LÝ DỰ ÁN | C28: TT12/2021/TT-BXD = | D28: =F18 -> 4.7346435e+10 | E28: =IF($D$28<=10*10^9,3.024%,IF($D$28<=20*10^9,3.024%-($D$28-10*10^9)*(3.024%-2.566%)/(10*10^9),IF($D$28<=50*10^9,2.566%-($D$28-20*10^9)*(2.566%-2.292%)/(30*10^9),IF($D$28<=100*10^9,2.292%-($D$28-50*10^9)*(2.292%-1.771%)/(50*10^9),IF($D$28<=200*10^9,1.771%-($D$28-100*10^9)*(1.771%-1.655%)/(100*10^9),IF($D$28<=500*10^9,1.655%-($D$28-200*10^9)*(1.655%-1.329%)/(300*10^9),IF($D$28<=1000*10^9,1.329%-($D$28-500*10^9)*(1.329%-1.088%)/(500*10^9)))))))) -> 0.023162359 | F28: =D28*E28 -> 1.0966551e+09 | H28: =ROUND((G28+F28),-3) -> 1096655000 | I28: GQLDA | J28: =2.566%-(2.566%-2.292%)/(50-20)*($F$18/10^9-20) -> 0.023162359 | M28: =H29-M29 -> 2315278000 | O28: =+O18*15/100 -> 7812161850
A29: IV | B29: CHI PHÍ TƯ VẤN ĐẦU TƯ XÂY DỰNG | F29: =SUM(F30:F72,F77) -> 4.4248542e+09 | G29: =SUM(G30:G72,G77) -> 4.4123849e+08 | H29: =ROUND((SUBTOTAL(9,H30:H72,H77)),-3) -> 4866092000 | I29: GTV | J29: sum thiếu phần trc thuế và phần thuế (đã sửa) | M29: 2550814000
A30: 1 | B30: Chi phí lập nhiệm vụ khảo sát, lập báo cáo đánh giá tác động môi trường, lập Báo cáo NCKT | C30: QĐ số 16/QĐ-BQLDA ngày 13/01/2023 | F30: =15886000/1.1 -> 14441818 | G30: =F30*10% -> 1444181.8 | H30: =ROUND((G30+F30),-3) -> 15886000 | M30: 2426258000
A31: 2 | B31: Chi phí thẩm tra nhiệm vụ dự toán chi phí khảo sát, lập báo cáo đánh giá tác động môi trường | C31: QĐ số 25/QĐ-BQLDA ngày 31/01/2023 | F31: =8825000/1.1 -> 8022727.3 | G31: =F31*10% -> 802272.73 | H31: =ROUND((G31+F31),-3) -> 8825000
B32: Chi phí khảo sát địa hình, cắm cọc giải phóng mặt bằng bước lập báo cáo NCKT | C32: QĐ số 60/QĐ-BQLDA ngày 23/3/2023 | F32: =[369]PLHĐ!$F$6/1.1 -> 3.3262847e+08 | G32: =F32*10% -> 33262847 | H32: =ROUND((G32+F32),-3) -> 365891000
A33: 4 | B33: Chi phí khảo sát địa chất bước lập báo cáo NCKT | C33: QĐ số 60/QĐ-BQLDA ngày 23/3/2023 | F33: =[369]PLHĐ!$F$44/1.1 -> 2.1552983e+08 | G33: =F33*10% -> 21552983 | H33: =ROUND((G33+F33),-3) -> 237083000
A34: =#REF!+1 -> #REF! | B34: Chi phí khảo sát địa chất lập Báo cáo NCKT | C34: Dự toán chi tiết | G34: =F34*10% -> 0 | H34: =F34+G34 -> 0 | L34: =+#REF!+H36 -> #REF!
A35: 5 | B35: Chi phí giám sát khảo sát bước lập báo cáo NCKT | C35: QĐ số 25/QĐ-BQLDA ngày 31/01/2023 | F35: =24748000/1.1 -> 22498182 | G35: =F35*10% -> 2249818.2 | H35: =ROUND(F35+G35,-3) -> 24748000
A36: 6 | B36: Chi phí lập Báo cáo nghiên cứu khả thi | C36: QĐ số 60/QĐ-BQLDA ngày 23/3/2023 | E36: =IF($K$35<=15*10^9,0.689%,IF($K$35<=20*10^9,0.689%-($K$35-15*10^9)*(0.689%-0.628%)/(5*10^9),IF($K$35<=50*10^9,0.628%-($K$35-20*10^9)*(0.628%-0.501%)/(30*10^9),IF($K$35<=100*10^9,0.501%-($K$35-50*10^9)*(0.501%-0.393%)/(50*10^9),IF($K$35<=200*10^9,0.393%-($K$35-100*10^9)*(0.393%-0.271%)/(100*10^9),IF($K$35<=500*10^9,0.271%-($K$35-200*10^9)*(0.271%-0.203%)/(300*10^9),IF($K$35<=1000*10^9,0.203%-($K$35-500*10^9)*(0.203%-0.177%)/(500*10^9)))))))) -> 0.00689 | F36: =[369]PLHĐ!$F$68/1.1 -> 2.6395727e+08 | G36: =F36*10% -> 26395727 | H36: =ROUND(F36+G36,-3) -> 290353000 | J36: =0.628%-(0.628%-0.501%)/(50-20)*($F$18/10^9-20) -> 0.0051223342 | K36: so sánh với giá trị trong HĐ thằng nào bé thì lấy
A37: 7 | B37: Chi phí thẩm tra Báo cáo nghiên cứu khả thi | C37: QĐ số 39/QĐ-BQLDA ngày 09/02/2023 | F37: =56271000/1.1 -> 51155455 | G37: =F37*10% -> 5115545.5 | H37: =ROUND(F37+G37,-3) -> 56271000 | J37: =0.139%-(0.139%-0.112%)/(50-20)*($F$18/10^9-20) -> 0.0011438821 | K37: so sánh với giá trị trong HĐ thằng nào bé thì lấy
A38: 8 | B38: Chi phí khảo sát, lập báo cáo đánh giá tác động môi trường | C38: QĐ số 25/QĐ-BQLDA ngày 31/01/2023 | F38: =367310000/1.1 -> 3.3391818e+08 | G38: =F38*10% -> 33391818 | H38: =ROUND(F38+G38,-3) -> 367310000 | K38: 177216000
A39: 9 | B39: Chi phí lập Nhiệm vụ khảo sát bước thiết kế BVTC | C39: Gks trước thuế x tỷ lệ | D39: =F40 -> 1.6110545e+08 | E39: 0.03 | F39: =(F40)*3% -> 4833163.6 | G39: =F39*10% -> 483316.36 | H39: =ROUND(F39+G39,-3) -> 5316000 | K39: =+H40-K38 -> 0
A40: =A39+1 -> 10 | B40: Chi phí khảo sát địa hình bước thiết kế BVTC | C40: Tạm tính | F40: 1.6110545e+08 | G40: =F40*10% -> 16110545 | H40: =ROUND(F40+G40,-3) -> 177216000 | L40: =+H40+H42 -> 888562000
...

Sheet Tổng mức đầu tư
A1: BẢNG TỔNG HỢP TỔNG MỨC ĐẦU TƯ XÂY DỰNG
A2: (Căn cứ theo Thông tư 12/2021/TT-BXD ngày 31 tháng 8 năm 2021)
H3: Hải Dương , ngày .tháng 6 năm 2023
A4: ='[374]Công trình'!A3 -> CÔNG TRÌNH: DI CHUYỂN ĐƯỜNG DÂY CAO HẠ THẾ PHỤC VỤ GPMB CẢI TẠO NÂNG CẤP ĐƯỜNG HUYỆN 195, GIAI ĐOẠN II
B5: Loại công trình: | E5: Công trình công nghiệp
B6: Loại thiết kế: | E6: Thiết kế 1 bước
B7: Cấp công trình: | E7: Cấp IV
B8: Cách thẩm định: | E8: Tự thẩm định toàn bộ
J9: Đơn vị tính: đồng
A10: STT | B10: NỘI DUNG CHI PHÍ | C10: Mã chi phí | D10: Bảng chi phí | E10: Tỷ lệ % | F10: Hệ số | G10: CÁCH TÍNH | H10: GIÁ TRỊ TRƯỚC THUẾ | I10: THUẾ GTGT | J10: GIÁ TRỊ SAU THUẾ | K10: KÝ HIỆU
A11: 1 | B11: Vật tư thu hồi GPMB | H11: =0 -> 0 | I11: =ROUND(H11*'[374]Hệ số'!C10,0) -> 0 | J11: =ROUND(H11+I11,0) -> 0 | K11: Gvtth
A12: 2 | B12: Chi phí xây dựng | H12: =H13 -> 842790367 | I12: =I13 -> 85000000 | J12: =J13 -> 927790367 | K12: Gxd
A13: 2.1 | B13: Chi phí xây dựng công trình chính | C13: CPXD | D13: CPXD | H13: =SUM(H14:H18) -> 842790367 | I13: 85000000 | J13: =ROUND(H13+I13,0) -> 927790367
A14: 2.1.1 | B14: ĐZ35KV - PHẦN XÂY DỰNG MÓNG | F14: 1 | G14: Theo bảng tổng hợp dự toán hạng mục | H14: ='[374]TH dự toán hạng mục'!D20*F14 -> 18864055 | I14: ='[374]TH dự toán hạng mục'!D21*F14 -> 1886406 | J14: =ROUND(H14+I14,0) -> 20750461
A15: 2.1.2 | B15: ĐZ 35kV- phần xây lắp | F15: 1 | G15: Theo bảng tổng hợp dự toán hạng mục | H15: ='[374]TH dự toán hạng mục'!D56*F15 -> 87888020 | I15: ='[374]TH dự toán hạng mục'!D57*F15 -> 8788802 | J15: =ROUND(H15+I15,0) -> 96676822
A16: 2.1.3 | B16: Hạng mụ Đường dây 0,4kV - Phần xây lắp đường dây | F16: 1 | G16: Theo bảng tổng hợp dự toán hạng mục | H16: ='[374]TH dự toán hạng mục'!D92*F16 -> 645980362 | I16: ='[374]TH dự toán hạng mục'!D93*F16 -> 64598036 | J16: =ROUND(H16+I16,0) -> 710578398
A17: 2.1.4 | B17: Đường dây 0,4kV - Phần xây dựng | F17: 1 | G17: Theo bảng tổng hợp dự toán hạng mục | H17: ='[374]TH dự toán hạng mục'!D128*F17 -> 86485485 | I17: ='[374]TH dự toán hạng mục'!D129*F17 -> 8648549 | J17: =ROUND(H17+I17,0) -> 95134034
A18: 2.1.5 | B18: Phần thí nghiệm | F18: 1 | G18: Theo bảng tổng hợp dự toán hạng mục | H18: ='[374]TH dự toán hạng mục'!D164*F18 -> 3572445 | I18: ='[374]TH dự toán hạng mục'!D165*F18 -> 357245 | J18: =ROUND(H18+I18,0) -> 3929690
A19: 3 | B19: Chi phí thiết bị | G19: Theo bảng tổng hợp chi phí TB | K19: Gtb
A20: 4 | B20: Chi phí quản lý dự án | C20: QLDA | D20: QLDA12 | E20: 0.03557 | G20: (Gxd+Gtb) trước thuế x tỷ lệ | H20: =ROUND((H12+H19)*E20,0) -> 29978053 | I20: =ROUND(H20*'[374]Hệ số'!C10,0) -> 2997805 | J20: =ROUND(H20+I20,0) -> 32975858 | K20: Gqlda
A21: 5 | B21: Chi phí tư vấn đầu tư xây dựng | H21: =SUM(H22:H51) -> 1.2986338e+08 | I21: =SUM(I22:I51) -> 12986338 | J21: =SUM(J22:J51) -> 142850000 | K21: Gtv
A22: 5.1 | B22: Chi phí khảo sát địa chất | C22: KSDC | D22: KSDC | H22: =0*(0) -> 0 | I22: =0*(ROUND(H22*'[374]Hệ số'!C10,0)) -> 0 | J22: =0*(ROUND(H22+I22,0)) -> 0
A23: 5.1 | B23: Chi phí khảo sát địa hình | C23: KSDH | D23: KSDH | H23: =[375]THKS!$E$19 -> 29651004 | I23: =ROUND(H23*'[374]Hệ số'!C10,0) -> 2965100 | J23: =ROUND(H23+I23,-3) -> 32616000
A24: 5.2 | B24: Chi phí lập nhiệm vụ khảo sát xây dựng | C24: NVKS | D24: NVKS | E24: 0.03 | G24: Gks trước thuế x tỷ lệ | H24: =+E24*H23 -> 889530.11 | I24: =ROUND(H24*'[374]Hệ số'!C10,0) -> 88953 | J24: =ROUND(H24+I24,-3) -> 978000
A25: 5.4 | B25: Chi phí lập báo cáo nghiên cứu tiền khả thi (Thông tư 12/2021/TT-BXD) | C25: NCTKT | D25: NCTKT12 | E25: 0.00757 | G25: (Gxd+Gtb) trước thuế x tỷ lệ | H25: =0*(ROUND((H12+H19)*E25,0)) -> 0 | I25: =0*(ROUND(H25*'[374]Hệ số'!C10,0)) -> 0 | J25: =0*(ROUND(H25+I25,0)) -> 0
A26: 5.5 | B26: Chi phí lập báo cáo nghiên cứu khả thi (Thông tư 12/2021/TT-BXD) | C26: NCKT | D26: NCKT12 | E26: 0.01261 | G26: (Gxd+Gtb) trước thuế x tỷ lệ | H26: =0*(ROUND((H12+H19)*E26,0)) -> 0 | I26: =0*(ROUND(H26*'[374]Hệ số'!C10,0)) -> 0 | J26: =0*(ROUND(H26+I26,0)) -> 0
A27: 5.3 | B27: Chi phí lập báo cáo kinh tế - kỹ thuật (Thông tư 12/2021/TT-BXD) | C27: LBC | D27: LBC12 | E27: 0.067 | F27: 1.15 | G27: (Gxd+Gtb) trước thuế x tỷ lệ | H27: =MAX(ROUND((H12+H19)*E27*F27,0),IF(E27 > 0, 5000000, 0)) -> 64936998 | I27: =ROUND(H27*'[374]Hệ số'!C10,0) -> 6493700 | J27: =ROUND(H27+I27,-3) -> 71431000
A28: 5.7 | B28: Chi phí thẩm tra báo cáo nghiên cứu tiền khả thi (Thông tư 12/2021/TT-BXD) | C28: TTTKT | D28: TTTKT12 | E28: 0.00098 | G28: (Gxd+Gtb) trước thuế x tỷ lệ | H28: =0*(ROUND((H12+H19)*E28,0)) -> 0 | I28: =0*(ROUND(H28*'[374]Hệ số'!C10,0)) -> 0 | J28: =0*(ROUND(H28+I28,0)) -> 0
A29: 5.8 | B29: Chi phí thẩm tra báo cáo nghiên cứu khả thi (Thông tư 12/2021/TT-BXD) | C29: TTKT | D29: TTKT12 | E29: 0.00281 | G29: (Gxd+Gtb) trước thuế x tỷ lệ | H29: =0*(ROUND((H12+H19)*E29,0)) -> 0 | I29: =0*(ROUND(H29*'[374]Hệ số'!C10,0)) -> 0 | J29: =0*(ROUND(H29+I29,0)) -> 0
A30: 5.9 | B30: Chi phí thẩm tra Báo cáo kinh tế - kỹ thuật (Thông tư 12/2021/TT-BXD) | E30: =E34+E35 -> 0.00572 | F30: 1.2 | G30: Gxd trước thuế x tỷ lệ | H30: =0*(ROUND(H12*E30*F30,0)) -> 0 | I30: =0*(ROUND(H30*'[374]Hệ số'!C10,0)) -> 0 | J30: =0*(ROUND(H30+I30,0)) -> 0
A31: 5.10 | B31: Chi phí thi tuyển thiết kế kiến trúc | C31: TTTKKT | D31: TTTKKT | I31: =0*(ROUND(H31*'[374]Hệ số'!C10,0)) -> 0 | J31: =0*(ROUND(H31+I31,0)) -> 0
A32: 5.11 | B32: Chi phí thiết kế kỹ thuật (Thông tư 12/2021/TT-BXD) | C32: TKKT | D32: TKKT12 | G32: Gxd trước thuế x tỷ lệ | H32: =0*(ROUND(H12*E32,0)) -> 0 | I32: =0*(ROUND(H32*'[374]Hệ số'!C10,0)) -> 0 | J32: =0*(ROUND(H32+I32,0)) -> 0
A33: 5.3 | B33: Chi phí thiết kế bản vẽ thi công (Thông tư 12/2021/TT-BXD) | C33: TKBV | D33: TKKT12 | F33: =0.93*1.3 -> 1.209 | G33: Gxd trước thuế x tỷ lệ | H33: =0*(ROUND(H12*E33*F33,0)) -> 0 | I33: =0*(ROUND(H33*'[374]Hệ số'!C10,0)) -> 0 | J33: =0*(ROUND(H33+I33,0)) -> 0
A34: 5.4 | B34: Chi phí thẩm tra thiết kế xây dựng (Thông tư 12/2021/TT-BXD) | C34: TTTKXD | D34: TTTKXD12 | E34: 0.0029 | G34: Gxd trước thuế x tỷ lệ | H34: =MAX(ROUND(H12*E34,0),IF(E34 > 0, 2000000, 0)) -> 2444092 | I34: =ROUND(H34*'[374]Hệ số'!C10,0) -> 244409 | J34: =ROUND(H34+I34,-3) -> 2689000
A35: 5.5 | B35: Chi phí thẩm tra dự toán công trình (Thông tư 12/2021/TT-BXD) | C35: TTDT | D35: TTDT12 | E35: 0.00282 | G35: Gxd trước thuế x tỷ lệ | H35: =MAX(ROUND(H12*E35,0),IF(E35 > 0, 2000000, 0)) -> 2376669 | I35: =ROUND(H35*'[374]Hệ số'!C10,0) -> 237667 | J35: =ROUND(H35+I35,-3) -> 2614000
A36: 5.15 | B36: Chi phí thẩm tra dự toán gói thầu (Thông tư 12/2021/TT-BXD) | C36: TTDT | D36: TTDT12 | E36: 0.00282 | G36: Chi phí xây dựng trước thuế trong gói thầu x tỷ lệ | H36: =0*(MAX(ROUND('[374]Dự toán gói thầu xây dựng'!F5*E36,0),IF(E36 > 0, 2000000, 0))) -> 0 | I36: =0*(ROUND(H36*'[374]Hệ số'!C10,0)) -> 0 | J36: =0*(ROUND(H36+I36,0)) -> 0
A37: 5.16 | B37: Chi phí lập hồ sơ mời thầu, đánh giá hồ sơ dự thầu tư vấn (Thông tư 12/2021/TT-BXD) | C37: LHSTV79 | D37: LHSTV12 | E37: 0.00816 | G37: Gtv trước thuế x tỷ lệ | H37: =0*(ROUND(113191509*E37,0)) -> 0 | I37: =0*(ROUND(H37*'[374]Hệ số'!C10,0)) -> 0 | J37: =0*(ROUND(H37+I37,0)) -> 0
A38: 5.17 | B38: Chi phí lập hồ sơ mời thầu, đánh giá hồ sơ dự thầu thi công xây dựng (Thông tư 12/2021/TT-BXD) | C38: LXL | D38: LXL12 | E38: 0.00549 | G38: Dự toán gói thầu trước thuế x tỷ lệ | H38: =0*(ROUND('[374]Dự toán gói thầu xây dựng'!F14*E38,0)) -> 0 | I38: =0*(ROUND(H38*'[374]Hệ số'!C10,0)) -> 0 | J38: =0*(ROUND(H38+I38,0)) -> 0
A39: 5.18 | B39: Chi phí lập hồ sơ mời thầu, đánh giá hồ sơ dự thầu mua sắm vật tư, thiết bị (Thông tư 12/2021/TT-BXD) | C39: LTB | D39: LTB12 | E39: 0.00549 | G39: Gtb trước thuế x tỷ lệ | H39: =0*(ROUND(H19*E39,0)) -> 0 | I39: =0*(ROUND(H39*'[374]Hệ số'!C10,0)) -> 0 | J39: =0*(ROUND(H39+I39,0)) -> 0
A40: 5.6 | B40: Chi phí giám sát thi công xây dựng (Thông tư 12/2021/TT-BXD) | C40: GSTC | D40: GSTC12 | E40: 0.03508 | G40: Dự toán gói thầu XD trước thuế x tỷ lệ | H40: =ROUND('[374]Dự toán gói thầu xây dựng'!F14*E40,0) -> 29565086 | I40: =ROUND(H40*'[374]Hệ số'!C10,0) -> 2956509 | J40: =ROUND(H40+I40,-3) -> 32522000
...

Sheet THDT
B2: Phụ lục
B3: TỔNG HỢP DỰ TOÁN
A4: Dự án: Cải tạo, nâng cấp đường huyện 195, đoạn từ Km0 - Km4+300, huyện Thanh Miện, tỉnh Hải Dương
A5: Địa Điểm TC: Huyện Thanh Miện, tỉnh Hải Dương
A6: Hạng mục: Rà phá bom mìn, vật nổ
B8: TT | C8: Nội dung chi phí | D8: Ký hiệu | E8: Cách tính | F8: Thành tiền (đồng)
B10: 1 | C10: 2 | D10: 3 | E10: 4 | F10: 5
B11: I | C11: Chi phí trực tiếp
B12: 1 | C12: Chi phí vật liệu | D12: VL | E12: Theo bảng PTDT | F12: =[373]PTDT!I14 -> 6336086.2
B13: 2 | C13: Chi phí nhân công | D13: NC | E13: Theo bảng PTDT | F13: =[373]PTDT!J14 -> 1.4641439e+08
B14: 3 | C14: Chi phí máy | D14: M | E14: Theo bảng PTDT | F14: =[373]PTDT!K14 -> 75641390
C15: Cộng chi phí trực tiếp: | D15: T | E15: VL+NC+M | F15: =SUM(F12:F14) -> 2.2839186e+08
B16: II | C16: Chi phí chung | D16: C | E16: 40%*NC | F16: =40%*F13 -> 58565754
C17: Cộng giá thành dự toán | D17: Z | E17: T+C+TL | F17: =SUM(F15:F16) -> 2.8695762e+08
B18: IV | C18: Chi phí khác | D18: K | E18: K1+K2+…+K5 | F18: =SUM(F19:F23) -> 31416018
B19: 1 | C19: Chi phí khảo sát sát, lập PAKTTC và dự toán | D19: K1 | E19: 2,5%*Z | F19: =2.5%*F17 -> 7173940.4
B20: 2 | C20: Chi phí lán trại | D20: K2 | E20: 2,2%*T | F20: =2.2%*F15 -> 5024621 | I20: =+F18-F22-F21 -> 26546442
B21: 3 | C21: Chi phí thẩm định | D21: K3 | E21: Tối thiểu | F21: 2000000
B22: 4 | C22: Chi phí kiểm tra, giám định chất lượng thi công rà phá BMVN | D22: K4 | E22: 1%*Z | F22: =1%*F17 -> 2869576.2 | H22: =+F17+F20+F23 -> 3.0633012e+08
B23: 5 | C23: Chi phí vận chuyển và hủy bom đạn sau dò tìm | D23: K5 | E23: 5%*Z | F23: =5%*F17 -> 14347881
C24: Cộng giá trị dự toán | D24: Q | E24: Z+K | F24: =F17+F18 -> 3.1837364e+08
C25: Làm tròn: | F25: =ROUND(F24,-3) -> 318374000
B26: (Viết bằng chữ: Ba trăm mười tám triệu, ba trăm bảy mươi tư nghìn đồng)
B28: ĐƠN VỊ LẬP DỰ TOÁN | D28: ĐẠI DIỆN CHỦ ĐẦU TƯ
B29: PHÓ TỔNG GIÁM ĐỐC
B36: Thượng tá Trần Thanh Cương
